Workbook

Sheet 总览
A1: 智能食堂系统开发任务总览
A3: 指标 | B3: 数值 | C3: 说明 | E3: 使用方式
A4: 总任务数 | B4: =COUNTA(任务清单!$A$2:$A$165) -> 164 | C4: 任务清单中的全部任务 | E4: 1. 在“任务清单”中找到当前任务。 2. 完成后将“完成”列改为 ☑，并把“状态”改为 已完成。 3. 遇到问题时把“状态”改为 阻塞，并在备注中写原因。 4. “总览”页会自动统计整体进度和各阶段完成率。
A5: 已打勾任务 | B5: =COUNTIF(任务清单!$J$2:$J$165,"☑") -> 111 | C5: 完成列为 ☑
A6: 状态为已完成 | B6: =COUNTIF(任务清单!$K$2:$K$165,"已完成") -> 101 | C6: 状态列为已完成
A7: 进行中任务 | B7: =COUNTIF(任务清单!$K$2:$K$165,"进行中") -> 4 | C7: 状态列为进行中
A8: 阻塞任务 | B8: =COUNTIF(任务清单!$K$2:$K$165,"阻塞") -> 0 | C8: 状态列为阻塞
A9: 整体完成率 | B9: =IF(B4=0,0,B5/B4) -> 0.67682927 | C9: 按打勾任务计算
A12: 阶段 | B12: 总任务 | C12: 已打勾 | D12: 完成率 | E12: 进行中 | F12: 阻塞 | G12: 高优先级
A13: 0 项目准备 | B13: =COUNTIF(任务清单!$B$2:$B$165,A13) -> 5 | C13: =COUNTIFS(任务清单!$B$2:$B$165,A13,任务清单!$J$2:$J$165,"☑") -> 4 | D13: =IF(B13=0,0,C13/B13) -> 0.8 | E13: =COUNTIFS(任务清单!$B$2:$B$165,A13,任务清单!$K$2:$K$165,"进行中") -> 0 | F13: =COUNTIFS(任务清单!$B$2:$B$165,A13,任务清单!$K$2:$K$165,"阻塞") -> 0 | G13: =COUNTIFS(任务清单!$B$2:$B$165,A13,任务清单!$H$2:$H$165,"高") -> 5
A14: 1 本地开发环境 | B14: =COUNTIF(任务清单!$B$2:$B$165,A14) -> 7 | C14: =COUNTIFS(任务清单!$B$2:$B$165,A14,任务清单!$J$2:$J$165,"☑") -> 7 | D14: =IF(B14=0,0,C14/B14) -> 1 | E14: =COUNTIFS(任务清单!$B$2:$B$165,A14,任务清单!$K$2:$K$165,"进行中") -> 0 | F14: =COUNTIFS(任务清单!$B$2:$B$165,A14,任务清单!$K$2:$K$165,"阻塞") -> 0 | G14: =COUNTIFS(任务清单!$B$2:$B$165,A14,任务清单!$H$2:$H$165,"高") -> 7
A15: 2 数据库与基础组件 | B15: =COUNTIF(任务清单!$B$2:$B$165,A15) -> 13 | C15: =COUNTIFS(任务清单!$B$2:$B$165,A15,任务清单!$J$2:$J$165,"☑") -> 13 | D15: =IF(B15=0,0,C15/B15) -> 1 | E15: =COUNTIFS(任务清单!$B$2:$B$165,A15,任务清单!$K$2:$K$165,"进行中") -> 0 | F15: =COUNTIFS(任务清单!$B$2:$B$165,A15,任务清单!$K$2:$K$165,"阻塞") -> 0 | G15: =COUNTIFS(任务清单!$B$2:$B$165,A15,任务清单!$H$2:$H$165,"高") -> 13
A16: 3 后端工程骨架 | B16: =COUNTIF(任务清单!$B$2:$B$165,A16) -> 8 | C16: =COUNTIFS(任务清单!$B$2:$B$165,A16,任务清单!$J$2:$J$165,"☑") -> 7 | D16: =IF(B16=0,0,C16/B16) -> 0.875 | E16: =COUNTIFS(任务清单!$B$2:$B$165,A16,任务清单!$K$2:$K$165,"进行中") -> 0 | F16: =COUNTIFS(任务清单!$B$2:$B$165,A16,任务清单!$K$2:$K$165,"阻塞") -> 0 | G16: =COUNTIFS(任务清单!$B$2:$B$165,A16,任务清单!$H$2:$H$165,"高") -> 8
A17: 4 公共模块 | B17: =COUNTIF(任务清单!$B$2:$B$165,A17) -> 8 | C17: =COUNTIFS(任务清单!$B$2:$B$165,A17,任务清单!$J$2:$J$165,"☑") -> 8 | D17: =IF(B17=0,0,C17/B17) -> 1 | E17: =COUNTIFS(任务清单!$B$2:$B$165,A17,任务清单!$K$2:$K$165,"进行中") -> 0 | F17: =COUNTIFS(任务清单!$B$2:$B$165,A17,任务清单!$K$2:$K$165,"阻塞") -> 0 | G17: =COUNTIFS(任务清单!$B$2:$B$165,A17,任务清单!$H$2:$H$165,"高") -> 8
A18: 5 用户服务 | B18: =COUNTIF(任务清单!$B$2:$B$165,A18) -> 12 | C18: =COUNTIFS(任务清单!$B$2:$B$165,A18,任务清单!$J$2:$J$165,"☑") -> 11 | D18: =IF(B18=0,0,C18/B18) -> 0.91666667 | E18: =COUNTIFS(任务清单!$B$2:$B$165,A18,任务清单!$K$2:$K$165,"进行中") -> 0 | F18: =COUNTIFS(任务清单!$B$2:$B$165,A18,任务清单!$K$2:$K$165,"阻塞") -> 0 | G18: =COUNTIFS(任务清单!$B$2:$B$165,A18,任务清单!$H$2:$H$165,"高") -> 12
A19: 6 菜品菜单服务 | B19: =COUNTIF(任务清单!$B$2:$B$165,A19) -> 14 | C19: =COUNTIFS(任务清单!$B$2:$B$165,A19,任务清单!$J$2:$J$165,"☑") -> 14 | D19: =IF(B19=0,0,C19/B19) -> 1 | E19: =COUNTIFS(任务清单!$B$2:$B$165,A19,任务清单!$K$2:$K$165,"进行中") -> 0 | F19: =COUNTIFS(任务清单!$B$2:$B$165,A19,任务清单!$K$2:$K$165,"阻塞") -> 0 | G19: =COUNTIFS(任务清单!$B$2:$B$165,A19,任务清单!$H$2:$H$165,"高") -> 14
A20: 7 取餐排队服务 | B20: =COUNTIF(任务清单!$B$2:$B$165,A20) -> 13 | C20: =COUNTIFS(任务清单!$B$2:$B$165,A20,任务清单!$J$2:$J$165,"☑") -> 12 | D20: =IF(B20=0,0,C20/B20) -> 0.92307692 | E20: =COUNTIFS(任务清单!$B$2:$B$165,A20,任务清单!$K$2:$K$165,"进行中") -> 1 | F20: =COUNTIFS(任务清单!$B$2:$B$165,A20,任务清单!$K$2:$K$165,"阻塞") -> 0 | G20: =COUNTIFS(任务清单!$B$2:$B$165,A20,任务清单!$H$2:$H$165,"高") -> 13
A21: 8 订单服务 | B21: =COUNTIF(任务清单!$B$2:$B$165,A21) -> 14 | C21: =COUNTIFS(任务清单!$B$2:$B$165,A21,任务清单!$J$2:$J$165,"☑") -> 11 | D21: =IF(B21=0,0,C21/B21) -> 0.78571429 | E21: =COUNTIFS(任务清单!$B$2:$B$165,A21,任务清单!$K$2:$K$165,"进行中") -> 2 | F21: =COUNTIFS(任务清单!$B$2:$B$165,A21,任务清单!$K$2:$K$165,"阻塞") -> 0 | G21: =COUNTIFS(任务清单!$B$2:$B$165,A21,任务清单!$H$2:$H$165,"高") -> 14
A22: 9 网关服务 | B22: =COUNTIF(任务清单!$B$2:$B$165,A22) -> 8 | C22: =COUNTIFS(任务清单!$B$2:$B$165,A22,任务清单!$J$2:$J$165,"☑") -> 7 | D22: =IF(B22=0,0,C22/B22) -> 0.875 | E22: =COUNTIFS(任务清单!$B$2:$B$165,A22,任务清单!$K$2:$K$165,"进行中") -> 1 | F22: =COUNTIFS(任务清单!$B$2:$B$165,A22,任务清单!$K$2:$K$165,"阻塞") -> 0 | G22: =COUNTIFS(任务清单!$B$2:$B$165,A22,任务清单!$H$2:$H$165,"高") -> 8
A23: 10 中间件联调 | B23: =COUNTIF(任务清单!$B$2:$B$165,A23) -> 9 | C23: =COUNTIFS(任务清单!$B$2:$B$165,A23,任务清单!$J$2:$J$165,"☑") -> 9 | D23: =IF(B23=0,0,C23/B23) -> 1 | E23: =COUNTIFS(任务清单!$B$2:$B$165,A23,任务清单!$K$2:$K$165,"进行中") -> 0 | F23: =COUNTIFS(任务清单!$B$2:$B$165,A23,任务清单!$K$2:$K$165,"阻塞") -> 0 | G23: =COUNTIFS(任务清单!$B$2:$B$165,A23,任务清单!$H$2:$H$165,"高") -> 9
A24: 11 前端开发 | B24: =COUNTIF(任务清单!$B$2:$B$165,A24) -> 20 | C24: =COUNTIFS(任务清单!$B$2:$B$165,A24,任务清单!$J$2:$J$165,"☑") -> 8 | D24: =IF(B24=0,0,C24/B24) -> 0.4 | E24: =COUNTIFS(任务清单!$B$2:$B$165,A24,任务清单!$K$2:$K$165,"进行中") -> 0 | F24: =COUNTIFS(任务清单!$B$2:$B$165,A24,任务清单!$K$2:$K$165,"阻塞") -> 0 | G24: =COUNTIFS(任务清单!$B$2:$B$165,A24,任务清单!$H$2:$H$165,"高") -> 20
... A27: 14 验收与答辩 | B27: =COUNTIF(任务清单!$B$2:$B$165,A27) -> 7 | C27: =COUNTIFS(任务清单!$B$2:$B$165,A27,任务清单!$J$2:$J$165,"☑") -> 0 | D27: =IF(B27=0,0,C27/B27) -> 0 | E27: =COUNTIFS(任务清单!$B$2:$B$165,A27,任务清单!$K$2:$K$165,"进行中") -> 0 | F27: =COUNTIFS(任务清单!$B$2:$B$165,A27,任务清单!$K$2:$K$165,"阻塞") -> 0 | G27: =COUNTIFS(任务清单!$B$2:$B$165,A27,任务清单!$H$2:$H$165,"高") -> 7

Sheet 任务清单
A1: ID | B1: 阶段 | C1: 分类 | D1: 子任务 | E1: 具体要做 | F1: 前置依赖 | G1: 验收标准 | H1: 优先级 | I1: 预计工时(h) | J1: 完成 | K1: 状态 | L1: 计划开始 | M1: 计划结束 | N1: 实际完成 | O1: 备注
A2: 1 | B2: 0 项目准备 | C2: 范围确认 | D2: 固定最低可交付范围 | E2: 确认必须交付用户/菜单/订单/取餐/网关/四端前端/K3S部署；不做真实支付、一卡通、优惠券等扩展 | F2: 需求规格说明书、概要设计 | G2: 形成 README 中的 MVP 范围清单 | H2: 高 | I2: 2 | J2: ☑ | K2: 已完成
A3: 2 | B3: 0 项目准备 | C3: 仓库初始化 | D3: 创建 Git 仓库 | E3: 建立 backend、frontend、deploy、docs 目录；设置 .gitignore；首次提交 | F3: 无 | G3: 仓库结构清晰，可正常提交代码 | H3: 高 | I3: 2 | J3: ☑ | K3: 已完成
A4: 3 | B4: 0 项目准备 | C4: 规范制定 | D4: 提交规范与分支策略 | E4: 确定 feat/fix/docs/test/refactor/chore 提交前缀；main/dev 分支策略 | F4: Git 仓库 | G4: README 中记录规范 | H4: 高 | I4: 2 | J4: ☑ | K4: 已完成
A5: 4 | B5: 0 项目准备 | C5: 任务管理 | D5: 建立开发看板 | E5: 按本表阶段建立任务，看板可选 GitHub Issues/本 Excel | F5: 开发计划 | G5: 任务可追踪、可打勾 | H5: 高 | I5: 2 | J5: ☑ | K5: 已完成
A6: 5 | B6: 0 项目准备 | C6: 演示规划 | D6: 确定演示主流程 | E6: 设计演示数据：用户、商家窗口、菜品、订单、大屏 | F6: MVP 范围 | G6: 有一条完整演示脚本草稿 | H6: 高 | I6: 2 | J6: ☐ | K6: 暂缓
A7: 6 | B7: 1 本地开发环境 | C7: 基础工具 | D7: 安装 JDK 17 | E7: 安装并配置 JAVA_HOME；IDEA 能识别 JDK | F7: 无 | G7: java -version 显示 17 | H7: 高 | I7: 2 | J7: ☑ | K7: 已完成
A8: 7 | B8: 1 本地开发环境 | C8: 基础工具 | D8: 安装 Maven 3.9+ | E8: 配置本地仓库和镜像源 | F8: JDK | G8: mvn -v 正常 | H8: 高 | I8: 2 | J8: ☑ | K8: 已完成
A9: 8 | B9: 1 本地开发环境 | C9: 前端工具 | D9: 安装 Node.js 20+ 与 pnpm | E9: 配置包管理器和镜像源 | F9: 无 | G9: node -v、pnpm -v 正常 | H9: 高 | I9: 2 | J9: ☑ | K9: 已完成
A10: 9 | B10: 1 本地开发环境 | C10: 容器工具 | D10: 安装 Docker | E10: Docker Desktop 或 Linux Docker Engine 可用 | F10: 无 | G10: docker ps 正常 | H10: 高 | I10: 2 | J10: ☑ | K10: 已完成
A11: 10 | B11: 1 本地开发环境 | C11: 数据库工具 | D11: 安装 DBeaver/Navicat | E11: 能连接本地 MySQL 容器 | F11: Docker/MySQL | G11: 能查看数据库和表 | H11: 高 | I11: 2 | J11: ☑ | K11: 已完成
A12: 11 | B12: 1 本地开发环境 | C12: 接口工具 | D12: 安装 Apifox/Postman | E12: 建立接口项目和环境变量 gateway_base_url | F12: 无 | G12: 能发起测试请求 | H12: 高 | I12: 2 | J12: ☑ | K12: 已完成
A13: 12 | B13: 1 本地开发环境 | C13: K8S 工具 | D13: 安装 kubectl/Lens | E13: 为后续 K3S 部署准备管理工具 | F13: 无 | G13: kubectl version 可用 | H13: 高 | I13: 2 | J13: ☑ | K13: 已完成
... A26: 25 | B26: 2 数据库与基础组件 | C26: 初始化数据 | D26: 插入测试账号和基础业务数据 | E26: 插入 admin/user01/merchant01、商家窗口、分类、菜品、每日菜单库存 | F26: 四个业务库 | G26: 可用于完整演示流程 | H26: 高 | I26: 2 | J26: ☑ | K26: 已完成
A27: 26 | B27: 3 后端工程骨架 | C27: Maven | D27: 创建父工程 smart-canteen | E27: 统一管理 Spring Boot、Spring Cloud、SCA、MyBatis-Plus、Knife4j 等版本 | F27: JDK/Maven | G27: 父工程 mvn clean package 通过 | H27: 高 | I27: 3 | J27: ☑ | K27: 已完成 | O27: package通过，健康接口检查通过，成功注册到nacos
A28: 27 | B28: 3 后端工程骨架 | C28: 模块 | D28: 创建 common 模块 | E28: 创建公共 DTO、异常、枚举、工具类基础目录 | F28: 父工程 | G28: common 模块可被其他服务引用 | H28: 高 | I28: 2 | J28: ☑ | K28: 已完成
A29: 28 | B29: 3 后端工程骨架 | C29: 模块 | D29: 创建 user-service | E29: 配置端口 9001、Nacos、MySQL、Redis、Knife4j | F29: 父工程/Nacos/MySQL | G29: 服务启动并注册到 Nacos | H29: 高 | I29: 2 | J29: ☑ | K29: 已完成
A30: 29 | B30: 3 后端工程骨架 | C30: 模块 | D30: 创建 menu-service | E30: 配置端口 9002、Nacos、MySQL、Redis、MyBatis-Plus | F30: 父工程/Nacos/MySQL | G30: 服务启动并注册到 Nacos | H30: 高 | I30: 2 | J30: ☑ | K30: 已完成
A31: 30 | B31: 3 后端工程骨架 | C31: 模块 | D31: 创建 order-service | E31: 配置端口 9003、Nacos、MySQL、Redis、Feign、RocketMQ、Seata 依赖 | F31: 父工程/Nacos/MySQL | G31: 服务启动并注册到 Nacos | H31: 高 | I31: 2 | J31: ☑ | K31: 已完成
A32: 31 | B32: 3 后端工程骨架 | C32: 模块 | D32: 创建 pickup-service | E32: 配置端口 9004、Nacos、MySQL、Redis、WebSocket | F32: 父工程/Nacos/MySQL | G32: 服务启动并注册到 Nacos | H32: 高 | I32: 2 | J32: ☑ | K32: 已完成
A33: 32 | B33: 3 后端工程骨架 | C33: 模块 | D33: 创建 gateway-service | E33: 配置端口 9000、Gateway、Nacos、Redis | F33: 父工程/Nacos/Redis | G33: 服务启动并注册到 Nacos | H33: 高 | I33: 2 | J33: ☑ | K33: 已完成
A34: 33 | B34: 3 后端工程骨架 | C34: 文档 | D34: 整理本地启动脚本 | E34: 编写 start-local.md 或 README：基础组件和服务启动顺序 | F34: 所有服务骨架 | G34: 新环境可照文档启动 | H34: 高 | I34: 2 | J34: ☐ | K34: 未开始
A35: 34 | B35: 4 公共模块 | C35: 统一响应 | D35: 实现 Result<T> 和 PageResult<T> | E35: 封装 code/message/data、分页 records/total/size/current | F35: common 模块 | G35: 各服务能直接使用统一响应 | H35: 高 | I35: 2 | J35: ☑ | K35: 已完成
A36: 35 | B36: 4 公共模块 | C36: 错误体系 | D36: 实现错误码枚举 | E36: 定义 UNAUTHORIZED、FORBIDDEN、INVALID_STOCK、ORDER_EXPIRED 等错误码 | F36: 详细设计错误码 | G36: 错误码命名统一 | H36: 高 | I36: 2 | J36: ☑ | K36: 已完成
A37: 36 | B37: 4 公共模块 | C37: 异常处理 | D37: 实现通用异常类 | E37: BusinessException、UnauthorizedException、ForbiddenException、DuplicateSubmissionException | F37: 错误码 | G37: 服务能抛业务异常 | H37: 高 | I37: 2 | J37: ☑ | K37: 已完成
A38: 37 | B38: 4 公共模块 | C38: 枚举 | D38: 实现业务枚举 | E38: RoleEnum、OrderStatus、MealPeriod、CallType、VerifyType、InventoryChangeType、ResetRule | F38: 详细设计 | G38: 枚举值与数据库一致 | H38: 高 | I38: 2 | J38: ☑ | K38: 已完成
A39: 38 | B39: 4 公共模块 | C39: JWT | D39: 实现 JwtUtil | E39: 支持生成/解析 access_token、refresh_token、jti、userId、role、username | F39: jjwt 依赖 | G39: 单元测试通过 | H39: 高 | I39: 2 | J39: ☑ | K39: 已完成
... A88: 87 | B88: 8 订单服务 | C88: 取消 | D88: 实现用户取消订单 | E88: PENDING_PAY/PAID 可取消，PREPARING 1 分钟内可取消；释放库存并移除队列 | F88: menu/pickup Feign | G88: 取消后库存恢复 | H88: 高 | I88: 2 | J88: ☑ | K88: 已完成
A89: 88 | B89: 8 订单服务 | C89: 商家接单 | D89: 实现接单接口 | E89: 校验 PAID、商家窗口归属、接单超时；状态改 PREPARING；调用 pickup 入制作中 | F89: pickup-service | G89: 接单后有 pickupNo | H89: 高 | I89: 2 | J89: ☑ | K89: 已完成 | L89: 已实现商家接单/拒单/出餐接口，含状态校验、商家归属校验、接单超时、库存释放、pickup 队列流转与单测。
A90: 89 | B90: 8 订单服务 | C90: 商家拒单 | D90: 实现拒绝接单接口 | E90: PAID 状态可拒单；订单取消；释放库存 | F90: menu-service | G90: 拒单后库存恢复 | H90: 高 | I90: 2 | J90: ☑ | K90: 已完成 | L90: 已实现 PAID 拒单取消并调用 menu-service 释放库存。
A91: 90 | B91: 8 订单服务 | C91: 商家出餐 | D91: 实现出餐接口 | E91: PREPARING 状态改 READY；调用 pickup 生成二维码和自动叫号 | F91: pickup-service | G91: 大屏进入待取餐队列 | H91: 高 | I91: 2 | J91: ☑ | K91: 已完成 | L91: 已实现 PREPARING 出餐转 READY，调用 pickup-service 转待取餐、生成二维码并自动叫号。
A92: 91 | B92: 8 订单服务 | C92: 核销同步 | D92: 实现内部状态更新接口 | E92: pickup-service 调用更新 COMPLETED；调用 menu-service consume 库存 | F92: pickup-service/menu-service | G92: 核销后订单完成 | H92: 高 | I92: 2 | J92: ☑ | K92: 已完成 | L92: 已实现 /internal/order/{orderId}/complete：READY 幂等同步 COMPLETED，调用 menu-service consume，并由 pickup 核销成功后同步。
A93: 92 | B93: 8 订单服务 | C93: 配置 | D93: 实现订单配置接口 | E93: pay_timeout_minutes、accept_timeout_minutes、cancel_window_minutes 读取/修改/缓存 | F93: config 表/Redis | G93: 配置即时生效 | H93: 高 | I93: 2 | J93: ☑ | K93: 已完成 | L93: 已实现 /api/admin/order/config：查询刷新 Redis 缓存，修改正整数分钟配置并记录 updatedBy。
A94: 93 | B94: 8 订单服务 | C94: 异常补偿 | D94: 实现补偿任务 | E94: 库存释放失败、消费失败、核销同步失败等重试或记录异常 | F94: 核心流程 | G94: 异常可追踪 | H94: 高 | I94: 2 | J94: ☐ | K94: 未开始
A95: 94 | B95: 8 订单服务 | C95: 测试 | D95: 完成 order-service 测试 | E95: 下单、支付、取消、接单、出餐、核销、非法状态测试 | F95: 功能完成 | G95: 测试通过 | H95: 高 | I95: 2 | J95: ☐ | K95: 进行中 | L95: 已补商家流程、核销同步、订单配置、RocketMQ 超时消息、定时扫描兜底单测；Seata 代码配置已准备，等待容器环境真联调。
A96: 95 | B96: 9 网关服务 | C96: 路由 | D96: 配置基础路由 | E96: /api/user、/api/menu、/api/order、/api/pickup、/api/admin、/ws 路由到对应服务 | F96: Nacos/业务服务 | G96: 请求可经网关转发 | H96: 高 | I96: 2 | J96: ☑ | K96: 已完成 | L96: 已配置 user/menu/order/pickup/admin/ws 基础路由，order 管理配置路由已补齐。
A97: 96 | B97: 9 网关服务 | C97: 白名单 | D97: 配置公开接口 | E97: 注册、登录、刷新、可售菜单、公开队列、大屏 ws 免登录 | F97: 路由配置 | G97: 公开接口无需 JWT | H97: 高 | I97: 2 | J97: ☑ | K97: 已完成 | L97: 已实现方法级白名单：登录注册、可售菜单、公开分类/菜品详情、公开队列/大屏 ws。
A98: 97 | B98: 9 网关服务 | C98: JWT 鉴权 | D98: 实现 AuthGlobalFilter | E98: 校验 Bearer token、签名、过期、Redis 黑名单；注入用户 Header | F98: user-service Token | G98: 未登录返回 401 | H98: 高 | I98: 2 | J98: ☑ | K98: 已完成 | L98: 已实现 AuthGlobalFilter：校验 Bearer token、签名、过期、Redis 黑名单，并注入 X-User-*。
A99: 98 | B99: 9 网关服务 | C99: 角色控制 | D99: 实现 RoleRouteFilter | E99: ADMIN/MERCHANT/USER 路径角色拦截 | F99: JWT 鉴权 | G99: 越权返回 403 | H99: 高 | I99: 2 | J99: ☑ | K99: 已完成 | L99: 已实现 ADMIN/MERCHANT 路径角色拦截；普通受保护接口交由后端做细粒度归属校验。
A100: 99 | B100: 9 网关服务 | C100: 限流 | D100: 实现 Redis + Lua 限流 | E100: IP 100 req/s，用户 50 req/s，敏感接口 5 req/min | F100: Redis | G100: 超限返回 429 | H100: 高 | I100: 2 | J100: ☑ | K100: 已完成 | L100: 已实现 Redis + Lua 令牌桶限流：IP 100 req/s、用户 50 req/s、敏感接口 5 req/min，超限返回 429。
...

Sheet 关键流程检查
A1: 序号 | B1: 检查分类 | C1: 检查项 | D1: 操作步骤 | E1: 预期结果 | F1: 完成 | G1: 状态 | H1: 备注
A2: 1 | B2: 核心业务流 | C2: 正常点餐取餐 | D2: 用户下单→支付→商家接单→出餐→自动叫号→用户展示二维码→商家核销 | E2: 订单状态从 PENDING_PAY 到 COMPLETED；库存和队列正确变化 | F2: ☑ | G2: 已完成 | H2: 后端主流程已闭环到 COMPLETED：下单、支付、接单、出餐、核销同步、库存消费均已实现，待端到端联调。
A3: 2 | B3: 核心业务流 | C3: 待支付手动取消 | D3: 用户创建订单后不支付，直接取消 | E3: 订单 CANCELLED；库存恢复；无队列数据 | F3: ☐ | G3: 未开始
A4: 3 | B4: 核心业务流 | C4: 支付超时自动取消 | D4: 创建订单后超过支付超时时间不支付 | E4: RocketMQ 或定时任务取消订单并恢复库存 | F4: ☐ | G4: 未开始
A5: 4 | B5: 核心业务流 | C5: 接单超时自动取消 | D5: 用户支付后商家不接单直到超时 | E5: 订单取消，库存恢复 | F5: ☐ | G5: 未开始
A6: 5 | B6: 核心业务流 | C6: 商家拒单 | D6: 用户支付后商家点击拒绝接单 | E6: 订单取消，库存恢复 | F6: ☑ | G6: 已完成 | H6: 后端接口已实现：PAID 拒单取消并释放库存，待后续联调复核。
A7: 6 | B7: 核心业务流 | C7: 接单后限时取消 | D7: 商家接单后用户在配置窗口内取消 | E7: 订单取消，从制作中队列移除，库存恢复 | F7: ☐ | G7: 未开始
A8: 7 | B8: 队列与叫号 | C8: 大屏制作中队列 | D8: 商家接单后观察大屏 | E8: 制作中队列出现取餐号 | F8: ☑ | G8: 已完成 | H8: 接单后调用 pickup 入制作中队列并生成取餐号，待大屏联调复核。
A9: 8 | B9: 队列与叫号 | C9: 大屏待取餐队列 | D9: 商家出餐后观察大屏 | E9: 订单从制作中移到待取餐，并出现叫号弹窗 | F9: ☑ | G9: 已完成 | H9: 出餐后调用 pickup 转待取餐、生成二维码并自动叫号，待大屏联调复核。
A10: 9 | B10: 队列与叫号 | C10: 手动叫号 | D10: 商家对 READY 订单点击手动叫号 | E10: 生成 MANUAL 叫号事件，大屏提示 | F10: ☐ | G10: 未开始
A11: 10 | B11: 取餐核销 | C11: 扫码核销 | D11: 用户展示二维码，商家扫码核销 | E11: 二维码失效，订单 COMPLETED，待取餐队列移除 | F11: ☑ | G11: 已完成 | H11: 扫码核销路径已同步 order-service 完成订单，并从待取餐队列移除。
A12: 11 | B12: 取餐核销 | C12: 手动取餐码核销 | D12: 商家输入取餐码核销 | E12: 与扫码核销结果一致 | F12: ☑ | G12: 已完成 | H12: 手动取餐码核销走同一同步逻辑。
A13: 12 | B13: 异常与幂等 | C13: 重复提交订单 | D13: 同一 X-Idempotent-Key 重复提交同一请求 | E13: 返回同一订单，不重复扣库存 | F13: ☐ | G13: 未开始
A14: 13 | B14: 异常与幂等 | C14: 重复核销 | D14: 同一二维码核销两次 | E14: 第二次返回取餐码无效或已核销 | F14: ☐ | G14: 未开始
A15: 14 | B15: 安全权限 | C15: 未登录访问受保护接口 | D15: 不带 token 调用下单/订单详情 | E15: 返回 401 | F15: ☐ | G15: 未开始
A16: 15 | B16: 安全权限 | C16: 角色越权 | D16: 普通用户访问商家接口或商家访问管理员接口 | E16: 返回 403 | F16: ☐ | G16: 未开始
A17: 16 | B17: 部署检查 | C17: K3S 服务健康 | D17: 检查 Pod、Service、Nacos 注册情况 | E17: 所有服务 Running，Gateway 可访问 | F17: ☐ | G17: 未开始
A18: 17 | B18: 部署检查 | C18: 前端线上访问 | D18: 访问 /user /merchant /admin /screen | E18: 四端页面可打开，接口和 WebSocket 正常 | F18: ☐ | G18: 未开始

Sheet 使用说明
A1: 使用说明
A2: 1. “任务清单”是主表，每一行是一个可执行任务。
A3: 2. 完成任务后，在“完成”列选择 ☑，并把“状态”改成“已完成”。
A4: 3. 如果任务还没开始，保持“完成=☐”“状态=未开始”。
A5: 4. 如果正在做，状态改为“进行中”。如果被卡住，状态改为“阻塞”，并在备注写清楚原因。
A6: 5. “总览”页会根据任务清单自动统计总任务数、完成数、阻塞数和各阶段完成率。
A7: 6. “关键流程检查”用于开发后期验收，建议每次部署前跑一遍。
A8: 7. 建议每完成一个小任务就提交 Git，不要等一个阶段全部完成再提交。
A9: 状态选项：未开始、进行中、已完成、阻塞、暂缓。
A10: 完成选项：☐、☑。
A11: 8. 部署阶段注意：MySQL 按架构文档部署在 K3S 集群外部；K3S 内只部署 Nacos、Redis、RocketMQ、Seata 和业务服务。
